Workbook
Name UPDATE: 'Data Sheet'!$E$1

Sheet Data Sheet
A1: COMPANY NAME | B1: MAHINDRA & MAHINDRA LTD | E1: =IF(B2<>B3, "A NEW VERSION OF THE WORKSHEET IS AVAILABLE", "")
A2: LATEST VERSION | B2: 2.1 | E2: PLEASE DO NOT MAKE ANY CHANGES TO THIS SHEET
A3: CURRENT VERSION | B3: 2.1
A5: META
A6: Number of shares | B6: =IF(B9>0, B9/B8, 0) -> 124.35289
A7: Face Value | B7: 5
A8: Current Price | B8: 3126
A9: Market Capitalization | B9: 388727.12
A15: PROFIT & LOSS
A16: Report Date | B16: 42460 | C16: 42825 | D16: 43190 | E16: 43555 | F16: 43921 | G16: 44286 | H16: 44651 | I16: 45016 | J16: 45382 | K16: 45747
A17: Sales | B17: 75841.42 | C17: 83773.05 | D17: 92093.95 | E17: 104720.68 | F17: 75381.93 | G17: 74277.78 | H17: 90170.57 | I17: 121268.55 | J17: 139078.27 | K17: 159210.82
A18: Raw Material Cost | B18: 45584.35 | C18: 50655.2 | D18: 53457.29 | E18: 61881.19 | F18: 37595.3 | G18: 38271.2 | H18: 52664.85 | I18: 76019.87 | J18: 85070.07 | K18: 95754.9
A19: Change in Inventory | B19: 458.51 | C19: 13.83 | D19: -83.33 | E19: 1730.48 | F19: -826.62 | G19: -135.59 | H19: 861.66 | I19: 2032.31 | J19: 1455.32 | K19: 12.18
A20: Power and Fuel | B20: 639.97 | C20: 657.06 | D20: 733.9 | E20: 817.11 | F20: 530.92 | G20: 429.56 | H20: 541.27 | I20: 830.48 | J20: 752.73 | K20: 832.35
A21: Other Mfr. Exp | B21: 2618.7 | C21: 3255.3 | D21: 3590.26 | E21: 4253 | F21: 3277.79 | G21: 2523.4 | H21: 3124.27 | I21: 3838.42 | J21: 3791.75 | K21: 4162.28
A22: Employee Cost | B22: 7689.4 | C22: 8910.63 | D22: 10004.62 | E22: 11242.08 | F22: 8214.82 | G22: 7813.26 | H22: 8386.74 | I22: 9677.95 | J22: 10624.33 | K22: 11126.17
A23: Selling and admin | B23: 5758.86 | C23: 6253.64 | D23: 7591.15 | E23: 9658.98 | F23: 6316.52 | G23: 4628.75 | H23: 5977.67 | I23: 7681.87 | J23: 9832.2 | K23: 10811.4
A24: Other Expenses | B24: 3926.21 | C24: 3320.22 | D24: 3407.3 | E24: 3392.29 | F24: 8462.21 | G24: 8989 | H24: 5654.58 | I24: 4966.98 | J24: 5570.58 | K24: 6017.71
A25: Other Income | B25: 1398.83 | C25: 2076.61 | D25: 4366.41 | E25: 2676.45 | F25: 884.69 | G25: 1151.51 | H25: 3204.47 | I25: 3961.45 | J25: 3297.85 | K25: 3718.47
A26: Depreciation | B26: 2441.65 | C26: 2812.72 | D26: 3279.9 | E26: 3990.77 | F26: 3366.68 | G26: 3378.11 | H26: 3507.5 | I26: 4356.81 | J26: 4723.78 | K26: 6073.65
A27: Interest | B27: 3367.59 | C27: 3648.46 | D27: 3987.09 | E27: 5021.35 | F27: 6021.15 | G27: 6102.22 | H27: 5018.05 | I27: 5829.7 | J27: 7488.21 | K27: 9083.39
... A31: Dividend Amount | B31: 648.96 | C31: 807.43 | D31: 814.7 | E31: 924.73 | F31: 260.51 | G31: 971.51 | H31: 1284.5 | I31: 1809.66 | J31: 2352.14 | K31: 2824.24
A40: Quarters
A41: Report Date | B41: 45199 | C41: 45291 | D41: 45382 | E41: 45473 | F41: 45565 | G41: 45657 | H41: 45747 | I41: 45838 | J41: 45930 | K41: 46022
A42: Sales | B42: 34435.52 | C42: 35299.39 | D42: 35451.73 | E42: 37217.72 | F42: 37923.74 | G42: 41470.05 | H42: 42599.31 | I42: 45529.19 | J42: 46105.67 | K42: 52099.75
A43: Expenses | B43: 28705.94 | C43: 29075.41 | D43: 28847.82 | E43: 29974.6 | F43: 30790.34 | G43: 33239.32 | H43: 34688.37 | I43: 37301.39 | J43: 37165.76 | K43: 41939.37
A44: Other Income | B44: 811.95 | C44: 755.69 | D44: 750.44 | E44: 733.21 | F44: 1125.57 | G44: 718.59 | H44: 1141.1 | I44: 1395.06 | J44: 1133.94 | K44: 976.43
A45: Depreciation | B45: 1138.64 | C45: 1122.59 | D45: 1335.05 | E45: 1247.77 | F45: 1301.99 | G45: 1495.17 | H45: 2028.72 | I45: 1547.56 | J45: 1668.89 | K45: 2162.89
A46: Interest | B46: 1835.19 | C46: 1944.88 | D46: 1989.3 | E46: 2107.69 | F46: 2217.02 | G46: 2362.16 | H46: 2396.52 | I46: 2431.19 | J46: 2347.03 | K46: 2405.3
A47: Profit before tax | B47: 3567.7 | C47: 3912.2 | D47: 4030 | E47: 4620.87 | F47: 4739.96 | G47: 5091.99 | H47: 4626.8 | I47: 5644.11 | J47: 6057.93 | K47: 6568.62
A48: Tax | B48: 1083.73 | C48: 935.16 | D48: 905.06 | E48: 1075.09 | F48: 1378.9 | G48: 1467.51 | H48: 1084.95 | I48: 1267.53 | J48: 2094.18 | K48: 1547.15
A49: Net profit | B49: 2347.75 | C49: 2658.4 | D49: 2754.08 | E49: 3282.63 | F49: 3170.72 | G49: 3180.58 | H49: 3295.17 | I49: 4083.32 | J49: 3673.32 | K49: 4674.64
A50: Operating Profit | B50: 5729.58 | C50: 6223.98 | D50: 6603.91 | E50: 7243.12 | F50: 7133.4 | G50: 8230.73 | H50: 7910.94 | I50: 8227.8 | J50: 8939.91 | K50: 10160.38
A55: BALANCE SHEET
A56: Report Date | B56: 42460 | C56: 42825 | D56: 43190 | E56: 43555 | F56: 43921 | G56: 44286 | H56: 44651 | I56: 45016 | J56: 45382 | K56: 45747
A57: Equity Share Capital | B57: 270.4 | C57: 310.55 | D57: 543.13 | E57: 543.96 | F57: 554.28 | G57: 555.15 | H57: 556.06 | I57: 556.82 | J57: 557.38 | K57: 558.15
A58: Reserves | B58: 26222.25 | C58: 29467.1 | D58: 36232.06 | E58: 39439.45 | F58: 39415.03 | G58: 41026.77 | H58: 46566.58 | I58: 55808.97 | J58: 65633.17 | K58: 76480.71
A59: Borrowings | B59: 41552.93 | C59: 48761.91 | D59: 55897.92 | E59: 70848.3 | F59: 82092.28 | G59: 80624.83 | H59: 77605.21 | I59: 92246.85 | J59: 108647.25 | K59: 129024.58
A60: Other Liabilities | B60: 31806.24 | C60: 35295.92 | D60: 43696.2 | E60: 51056.95 | F60: 43654.54 | G60: 42761.58 | H60: 47660.64 | I60: 55670.49 | J60: 59883.94 | K60: 69949.72
A61: Total | B61: 99851.82 | C61: 113835.48 | D61: 136369.31 | E61: 161888.66 | F61: 165716.13 | G61: 164968.33 | H61: 172388.49 | I61: 204283.13 | J61: 234721.74 | K61: 276013.16
...

Sheet Profit & Loss
A1: ='Data Sheet'!B1 -> MAHINDRA & MAHINDRA LTD | H1: =UPDATE | M1: SCREENER.IN
A3: Narration | B3: Mar-16 | C3: Mar-17 | D3: Mar-18 | E3: Mar-19 | F3: Mar-20 | G3: Mar-21 | H3: Mar-22 | I3: Mar-23 | J3: Mar-24 | K3: Mar-25 | L3: Trailing | M3: Best Case | N3: Worst Case
A4: Sales | B4: ='Data Sheet'!B17 -> 75841.42 | C4: ='Data Sheet'!C17 -> 83773.05 | D4: ='Data Sheet'!D17 -> 92093.95 | E4: ='Data Sheet'!E17 -> 104720.68 | F4: ='Data Sheet'!F17 -> 75381.93 | G4: ='Data Sheet'!G17 -> 74277.78 | H4: ='Data Sheet'!H17 -> 90170.57 | I4: ='Data Sheet'!I17 -> 121268.55 | ... K4: ='Data Sheet'!K17 -> 159210.82 | L4: =SUM(#REF!) -> #REF! | M4: =$K4+M23*K4 -> 192431.06 | N4: =$K4+N23*L4 -> #REF!
A5: Expenses | B5: =SUM('Data Sheet'!B18,'Data Sheet'!B20:B24, -1*'Data Sheet'!B19) -> 65758.98 | C5: =SUM('Data Sheet'!C18,'Data Sheet'!C20:C24, -1*'Data Sheet'!C19) -> 73038.22 | D5: =SUM('Data Sheet'!D18,'Data Sheet'!D20:D24, -1*'Data Sheet'!D19) -> 78867.85 | E5: =SUM('Data Sheet'!E18,'Data Sheet'!E20:E24, -1*'Data Sheet'!E19) -> 89514.17 | F5: =SUM('Data Sheet'!F18,'Data Sheet'!F20:F24, -1*'Data Sheet'!F19) -> 65224.18 | G5: =SUM('Data Sheet'!G18,'Data Sheet'!G20:G24, -1*'Data Sheet'!G19) -> 62790.76 | H5: =SUM('Data Sheet'!H18,'Data Sheet'!H20:H24, -1*'Data Sheet'!H19) -> 75487.72 | I5: =SUM('Data Sheet'!I18,'Data Sheet'!I20:I24, -1*'Data Sheet'!I19) -> 100983.26 | ... K5: =SUM('Data Sheet'!K18,'Data Sheet'!K20:K24, -1*'Data Sheet'!K19) -> 128692.63 | L5: =SUM(#REF!) -> #REF! | M5: =M4-M6 -> #REF! | N5: =N4-N6 -> #REF!
A6: Operating Profit | B6: =B4-B5 -> 10082.44 | C6: =C4-C5 -> 10734.83 | D6: =D4-D5 -> 13226.1 | E6: =E4-E5 -> 15206.51 | F6: =F4-F5 -> 10157.75 | G6: =G4-G5 -> 11487.02 | H6: =H4-H5 -> 14682.85 | I6: =I4-I5 -> 20285.29 | ... K6: =K4-K5 -> 30518.19 | L6: =SUM(#REF!) -> #REF! | M6: =M4*M24 -> #REF! | N6: =N4*N24 -> #REF!
A7: Other Income | B7: ='Data Sheet'!B25 -> 1398.83 | C7: ='Data Sheet'!C25 -> 2076.61 | D7: ='Data Sheet'!D25 -> 4366.41 | E7: ='Data Sheet'!E25 -> 2676.45 | F7: ='Data Sheet'!F25 -> 884.69 | G7: ='Data Sheet'!G25 -> 1151.51 | H7: ='Data Sheet'!H25 -> 3204.47 | I7: ='Data Sheet'!I25 -> 3961.45 | ... K7: ='Data Sheet'!K25 -> 3718.47 | L7: =SUM(#REF!) -> #REF! | M7: 0 | N7: 0
A8: Depreciation | B8: ='Data Sheet'!B26 -> 2441.65 | C8: ='Data Sheet'!C26 -> 2812.72 | D8: ='Data Sheet'!D26 -> 3279.9 | E8: ='Data Sheet'!E26 -> 3990.77 | F8: ='Data Sheet'!F26 -> 3366.68 | G8: ='Data Sheet'!G26 -> 3378.11 | H8: ='Data Sheet'!H26 -> 3507.5 | I8: ='Data Sheet'!I26 -> 4356.81 | ... K8: ='Data Sheet'!K26 -> 6073.65 | L8: =SUM(#REF!) -> #REF! | M8: =+$L8 -> #REF! | N8: =+$L8 -> #REF!
A9: Interest | B9: ='Data Sheet'!B27 -> 3367.59 | C9: ='Data Sheet'!C27 -> 3648.46 | D9: ='Data Sheet'!D27 -> 3987.09 | E9: ='Data Sheet'!E27 -> 5021.35 | F9: ='Data Sheet'!F27 -> 6021.15 | G9: ='Data Sheet'!G27 -> 6102.22 | H9: ='Data Sheet'!H27 -> 5018.05 | I9: ='Data Sheet'!I27 -> 5829.7 | ... K9: ='Data Sheet'!K27 -> 9083.39 | L9: =SUM(#REF!) -> #REF! | M9: =+$L9 -> #REF! | N9: =+$L9 -> #REF!
A10: Profit before tax | B10: ='Data Sheet'!B28 -> 5672.03 | C10: ='Data Sheet'!C28 -> 6350.26 | D10: ='Data Sheet'!D28 -> 10325.52 | E10: ='Data Sheet'!E28 -> 8870.84 | F10: ='Data Sheet'!F28 -> 1654.61 | G10: ='Data Sheet'!G28 -> 3158.2 | H10: ='Data Sheet'!H28 -> 9361.77 | I10: ='Data Sheet'!I28 -> 14060.23 | ... K10: ='Data Sheet'!K28 -> 19079.62 | L10: =SUM(#REF!) -> #REF! | M10: =M6+M7-SUM(M8:M9) -> #REF! | N10: =N6+N7-SUM(N8:N9) -> #REF!
A11: Tax | B11: ='Data Sheet'!B29 -> 2117.53 | C11: ='Data Sheet'!C29 -> 2299.73 | D11: ='Data Sheet'!D29 -> 2367.73 | E11: ='Data Sheet'!E29 -> 2853.99 | F11: ='Data Sheet'!F29 -> 1975.61 | G11: ='Data Sheet'!G29 -> 1645.81 | H11: ='Data Sheet'!H29 -> 2108.76 | I11: ='Data Sheet'!I29 -> 2685.75 | ... K11: ='Data Sheet'!K29 -> 5006.45 | L11: =SUM(#REF!) -> #REF! | M11: =IF($L10>0,$L11/$L10,0) -> #REF! | N11: =IF($L10>0,$L11/$L10,0) -> #REF!
A12: Net profit | B12: ='Data Sheet'!B30 -> 3148.43 | C12: ='Data Sheet'!C30 -> 3698.04 | D12: ='Data Sheet'!D30 -> 7510.39 | E12: ='Data Sheet'!E30 -> 5315.46 | F12: ='Data Sheet'!F30 -> 127.04 | G12: ='Data Sheet'!G30 -> 1812.49 | H12: ='Data Sheet'!H30 -> 6577.32 | I12: ='Data Sheet'!I30 -> 10281.5 | ... K12: ='Data Sheet'!K30 -> 12929.1 | L12: =SUM(#REF!) -> #REF! | M12: =M10-M11*M10 -> #REF! | N12: =N10-N11*N10 -> #REF!
A13: EPS | B13: =IF('Data Sheet'!B93>0,B12/'Data Sheet'!B93,0) -> 25.345597 | C13: =IF('Data Sheet'!C93>0,C12/'Data Sheet'!C93,0) -> 29.770085 | D13: =IF('Data Sheet'!D93>0,D12/'Data Sheet'!D93,0) -> 60.41176 | E13: =IF('Data Sheet'!E93>0,E12/'Data Sheet'!E93,0) -> 42.756274 | F13: =IF('Data Sheet'!F93>0,F12/'Data Sheet'!F93,0) -> 1.021879 | G13: =IF('Data Sheet'!G93>0,G12/'Data Sheet'!G93,0) -> 14.579231 | H13: =IF('Data Sheet'!H93>0,H12/'Data Sheet'!H93,0) -> 52.906371 | I13: =IF('Data Sheet'!I93>0,I12/'Data Sheet'!I93,0) -> 82.681946 | ... K13: =IF('Data Sheet'!K93>0,K12/'Data Sheet'!K93,0) -> 103.97346 | L13: =IF('Data Sheet'!$B6>0,'Profit & Loss'!L12/'Data Sheet'!$B6,0) -> #REF! | M13: =IF('Data Sheet'!$B6>0,'Profit & Loss'!M12/'Data Sheet'!$B6,0) -> #REF! | N13: =IF('Data Sheet'!$B6>0,'Profit & Loss'!N12/'Data Sheet'!$B6,0) -> #REF!
A14: Price to earning | B14: =IF(B15>0,B15/B13,"") -> 23.883833 | C14: =IF(C15>0,C15/C13,"") -> 21.613979 | D14: =IF(D15>0,D15/D13,"") -> 12.231062 | E14: =IF(E15>0,E15/E13,"") -> 15.761429 | F14: =IF(F15>0,F15/F13,"") -> 278.84906 | G14: =IF(G15>0,G15/G13,"") -> 54.546773 | H14: =IF(H15>0,H15/H13,"") -> 15.244856 | I14: =IF(I15>0,I15/I13,"") -> 14.013942 | ... K14: =IF(K15>0,K15/K13,"") -> 25.639235 | L14: =IF(L13>0,L15/L13,0) -> #REF! | M14: =M25 -> #REF! | N14: =N25 -> #REF!
A15: Price | B15: ='Data Sheet'!B90 -> 605.35 | C15: ='Data Sheet'!C90 -> 643.45 | D15: ='Data Sheet'!D90 -> 738.9 | E15: ='Data Sheet'!E90 -> 673.9 | F15: ='Data Sheet'!F90 -> 284.95 | G15: ='Data Sheet'!G90 -> 795.25 | H15: ='Data Sheet'!H90 -> 806.55 | I15: ='Data Sheet'!I90 -> 1158.7 | ... K15: ='Data Sheet'!K90 -> 2665.8 | L15: ='Data Sheet'!B8 -> 3126 | M15: =M13*M14 -> #REF! | N15: =N13*N14 -> #REF!
A17: RATIOS:
A18: Dividend Payout | B18: =IF('Data Sheet'!B30>0, 'Data Sheet'!B31/'Data Sheet'!B30, 0) -> 0.20612178 | C18: =IF('Data Sheet'!C30>0, 'Data Sheet'!C31/'Data Sheet'!C30, 0) -> 0.21833999 | D18: =IF('Data Sheet'!D30>0, 'Data Sheet'!D31/'Data Sheet'!D30, 0) -> 0.10847639 | E18: =IF('Data Sheet'!E30>0, 'Data Sheet'!E31/'Data Sheet'!E30, 0) -> 0.17396989 | F18: =IF('Data Sheet'!F30>0, 'Data Sheet'!F31/'Data Sheet'!F30, 0) -> 2.050614 | G18: =IF('Data Sheet'!G30>0, 'Data Sheet'!G31/'Data Sheet'!G30, 0) -> 0.53600847 | H18: =IF('Data Sheet'!H30>0, 'Data Sheet'!H31/'Data Sheet'!H30, 0) -> 0.19529231 | I18: =IF('Data Sheet'!I30>0, 'Data Sheet'!I31/'Data Sheet'!I30, 0) -> 0.17601128 | ... K18: =IF('Data Sheet'!K30>0, 'Data Sheet'!K31/'Data Sheet'!K30, 0) -> 0.21844057
A19: OPM | B19: =IF(B6>0,B6/B4,0) -> 0.13294108 | C19: =IF(C6>0,C6/C4,0) -> 0.12814181 | D19: =IF(D6>0,D6/D4,0) -> 0.1436153 | E19: =IF(E6>0,E6/E4,0) -> 0.14521019 | F19: =IF(F6>0,F6/F4,0) -> 0.13475046 | G19: =IF(G6>0,G6/G4,0) -> 0.15464948 | H19: =IF(H6>0,H6/H4,0) -> 0.16283417 | I19: =IF(I6>0,I6/I4,0) -> 0.16727577 | ... L19: =IF(L6>0,L6/L4,0) -> #REF!
G22: TRENDS: | H22: 10 YEARS | I22: 7 YEARS | J22: 5 YEARS | K22: 3 YEARS | L22: RECENT | M22: BEST | N22: WORST
G23: Sales Growth | H23: =IF(B4=0,"",POWER($K4/B4,1/9)-1) -> 0.085888228 | I23: =IF(D4=0,"",POWER($K4/D4,1/7)-1) -> 0.081341992 | J23: =IF(F4=0,"",POWER($K4/F4,1/5)-1) -> 0.16129101 | K23: =IF(H4=0,"",POWER($K4/H4, 1/3)-1) -> 0.20865565 | L23: =IF(ISERROR(MAX(IF(J4=0,"",(K4-J4)/J4),IF(K4=0,"",(L4-K4)/K4))),"",MAX(IF(J4=0,"",(K4-J4)/J4),IF(K4=0,"",(L4-K4)/K4))) | M23: =MAX(K23:L23) -> 0.20865565 | N23: =MIN(H23:L23) -> 0.081341992
G24: OPM | H24: =IF(SUM(B4:$K$4)=0,"",SUMPRODUCT(B19:$K$19,B4:$K$4)/SUM(B4:$K$4)) -> 0.15876177 | I24: =IF(SUM(E4:$K$4)=0,"",SUMPRODUCT(E19:$K$19,E4:$K$4)/SUM(E4:$K$4)) -> 0.16650714 | J24: =IF(SUM(G4:$K$4)=0,"",SUMPRODUCT(G19:$K$19,G4:$K$4)/SUM(G4:$K$4)) -> 0.17442506 | K24: =IF(SUM(I4:$K$4)=0, "", SUMPRODUCT(I19:$K$19,I4:$K$4)/SUM(I4:$K$4)) -> 0.18041719 | L24: =L19 -> #REF! | M24: =MAX(K24:L24) -> #REF! | N24: =MIN(H24:L24) -> #REF!
G25: Price to Earning | H25: =IF(ISERROR(AVERAGEIF(B14:$L14,">0")),"",AVERAGEIF(B14:$L14,">0")) -> 48.298636 | I25: =IF(ISERROR(AVERAGEIF(E14:$L14,">0")),"",AVERAGEIF(E14:$L14,">0")) -> 60.751069 | J25: =IF(ISERROR(AVERAGEIF(G14:$L14,">0")),"",AVERAGEIF(G14:$L14,">0")) -> 26.1294 | K25: =IF(ISERROR(AVERAGEIF(I14:$L14,">0")),"",AVERAGEIF(I14:$L14,">0")) -> 20.285123 | L25: =L14 -> #REF! | M25: =MAX(K25:L25) -> #REF! | N25: =MIN(H25:L25) -> #REF!

Sheet Balance Sheet
A1: ='Profit & Loss'!A1 -> MAHINDRA & MAHINDRA LTD | E1: =UPDATE | J1: SCREENER.IN
A3: Narration | B3: Mar-16 | C3: Mar-17 | D3: Mar-18 | E3: Mar-19 | F3: Mar-20 | G3: Mar-21 | H3: Mar-22 | I3: Mar-23 | J3: Mar-24 | K3: Mar-25
A4: Equity Share Capital | B4: ='Data Sheet'!B57 -> 270.4 | C4: ='Data Sheet'!C57 -> 310.55 | D4: ='Data Sheet'!D57 -> 543.13 | E4: ='Data Sheet'!E57 -> 543.96 | F4: ='Data Sheet'!F57 -> 554.28 | G4: ='Data Sheet'!G57 -> 555.15 | H4: ='Data Sheet'!H57 -> 556.06 | I4: ='Data Sheet'!I57 -> 556.82 | ... K4: ='Data Sheet'!K57 -> 558.15
A5: Reserves | B5: ='Data Sheet'!B58 -> 26222.25 | C5: ='Data Sheet'!C58 -> 29467.1 | D5: ='Data Sheet'!D58 -> 36232.06 | E5: ='Data Sheet'!E58 -> 39439.45 | F5: ='Data Sheet'!F58 -> 39415.03 | G5: ='Data Sheet'!G58 -> 41026.77 | H5: ='Data Sheet'!H58 -> 46566.58 | I5: ='Data Sheet'!I58 -> 55808.97 | ... K5: ='Data Sheet'!K58 -> 76480.71
A6: Borrowings | B6: ='Data Sheet'!B59 -> 41552.93 | C6: ='Data Sheet'!C59 -> 48761.91 | D6: ='Data Sheet'!D59 -> 55897.92 | E6: ='Data Sheet'!E59 -> 70848.3 | F6: ='Data Sheet'!F59 -> 82092.28 | G6: ='Data Sheet'!G59 -> 80624.83 | H6: ='Data Sheet'!H59 -> 77605.21 | I6: ='Data Sheet'!I59 -> 92246.85 | ... K6: ='Data Sheet'!K59 -> 129024.58
A7: Other Liabilities | B7: ='Data Sheet'!B60 -> 31806.24 | C7: ='Data Sheet'!C60 -> 35295.92 | D7: ='Data Sheet'!D60 -> 43696.2 | E7: ='Data Sheet'!E60 -> 51056.95 | F7: ='Data Sheet'!F60 -> 43654.54 | G7: ='Data Sheet'!G60 -> 42761.58 | H7: ='Data Sheet'!H60 -> 47660.64 | I7: ='Data Sheet'!I60 -> 55670.49 | ... K7: ='Data Sheet'!K60 -> 69949.72
A8: Total | B8: ='Data Sheet'!B61 -> 99851.82 | C8: ='Data Sheet'!C61 -> 113835.48 | D8: ='Data Sheet'!D61 -> 136369.31 | E8: ='Data Sheet'!E61 -> 161888.66 | F8: ='Data Sheet'!F61 -> 165716.13 | G8: ='Data Sheet'!G61 -> 164968.33 | H8: ='Data Sheet'!H61 -> 172388.49 | I8: ='Data Sheet'!I61 -> 204283.13 | ... K8: ='Data Sheet'!K61 -> 276013.16
A10: Net Block | B10: ='Data Sheet'!B62 -> 20584.71 | C10: ='Data Sheet'!C62 -> 20989.01 | D10: ='Data Sheet'!D62 -> 26181.9 | E10: ='Data Sheet'!E62 -> 28982.74 | F10: ='Data Sheet'!F62 -> 29689.27 | G10: ='Data Sheet'!G62 -> 21379.68 | H10: ='Data Sheet'!H62 -> 26018.49 | I10: ='Data Sheet'!I62 -> 27139.98 | ... K10: ='Data Sheet'!K62 -> 34636.36
A11: Capital Work in Progress | B11: ='Data Sheet'!B63 -> 2371.35 | C11: ='Data Sheet'!C63 -> 4278.94 | D11: ='Data Sheet'!D63 -> 4269.47 | E11: ='Data Sheet'!E63 -> 4759.84 | F11: ='Data Sheet'!F63 -> 6856.48 | G11: ='Data Sheet'!G63 -> 7872.61 | H11: ='Data Sheet'!H63 -> 6702.81 | I11: ='Data Sheet'!I63 -> 3968.58 | ... K11: ='Data Sheet'!K63 -> 8297.64
A12: Investments | B12: ='Data Sheet'!B64 -> 11602.58 | C12: ='Data Sheet'!C64 -> 14662.44 | D12: ='Data Sheet'!D64 -> 16017.61 | E12: ='Data Sheet'!E64 -> 18268.1 | F12: ='Data Sheet'!F64 -> 19210.34 | G12: ='Data Sheet'!G64 -> 28777.66 | H12: ='Data Sheet'!H64 -> 30060.43 | I12: ='Data Sheet'!I64 -> 35272.42 | ... K12: ='Data Sheet'!K64 -> 41308.57
A13: Other Assets | B13: ='Data Sheet'!B65 -> 65293.18 | C13: ='Data Sheet'!C65 -> 73905.09 | D13: ='Data Sheet'!D65 -> 89900.33 | E13: ='Data Sheet'!E65 -> 109877.98 | F13: ='Data Sheet'!F65 -> 109960.04 | G13: ='Data Sheet'!G65 -> 106938.38 | H13: ='Data Sheet'!H65 -> 109606.76 | I13: ='Data Sheet'!I65 -> 137902.15 | ... K13: ='Data Sheet'!K65 -> 191770.59
A14: Total | B14: ='Data Sheet'!B66 -> 99851.82 | C14: ='Data Sheet'!C66 -> 113835.48 | D14: ='Data Sheet'!D66 -> 136369.31 | E14: ='Data Sheet'!E66 -> 161888.66 | F14: ='Data Sheet'!F66 -> 165716.13 | G14: ='Data Sheet'!G66 -> 164968.33 | H14: ='Data Sheet'!H66 -> 172388.49 | I14: ='Data Sheet'!I66 -> 204283.13 | ... K14: ='Data Sheet'!K66 -> 276013.16
A16: Working Capital | B16: =B13-B7 -> 33486.94 | C16: =C13-C7 -> 38609.17 | D16: =D13-D7 -> 46204.13 | E16: =E13-E7 -> 58821.03 | F16: =F13-F7 -> 66305.5 | G16: =G13-G7 -> 64176.8 | H16: =H13-H7 -> 61946.12 | I16: =I13-I7 -> 82231.66 | ... K16: =K13-K7 -> 121820.87
A17: Debtors | B17: ='Data Sheet'!B67 -> 5817.6 | C17: ='Data Sheet'!C67 -> 7199.26 | D17: ='Data Sheet'!D67 -> 8489.82 | E17: ='Data Sheet'!E67 -> 8677.89 | F17: ='Data Sheet'!F67 -> 6928.28 | G17: ='Data Sheet'!G67 -> 6007.76 | H17: ='Data Sheet'!H67 -> 6373.95 | I17: ='Data Sheet'!I67 -> 7028.02 | ... K17: ='Data Sheet'!K67 -> 8279.7
A18: Inventory | B18: ='Data Sheet'!B68 -> 9116.12 | C18: ='Data Sheet'!C68 -> 8886.01 | D18: ='Data Sheet'!D68 -> 9335.57 | E18: ='Data Sheet'!E68 -> 12200.16 | F18: ='Data Sheet'!F68 -> 11111.86 | G18: ='Data Sheet'!G68 -> 9615.41 | H18: ='Data Sheet'!H68 -> 11595.82 | I18: ='Data Sheet'!I68 -> 16854.97 | ... K18: ='Data Sheet'!K68 -> 20330.93
A20: Debtor Days | B20: =IF('Profit & Loss'!B4>0,'Balance Sheet'!B17/('Profit & Loss'!B4/365),0) -> 27.99821 | C20: =IF('Profit & Loss'!C4>0,'Balance Sheet'!C17/('Profit & Loss'!C4/365),0) -> 31.367246 | D20: =IF('Profit & Loss'!D4>0,'Balance Sheet'!D17/('Profit & Loss'!D4/365),0) -> 33.648077 | E20: =IF('Profit & Loss'!E4>0,'Balance Sheet'!E17/('Profit & Loss'!E4/365),0) -> 30.24646 | F20: =IF('Profit & Loss'!F4>0,'Balance Sheet'!F17/('Profit & Loss'!F4/365),0) -> 33.546796 | G20: =IF('Profit & Loss'!G4>0,'Balance Sheet'!G17/('Profit & Loss'!G4/365),0) -> 29.522051 | H20: =IF('Profit & Loss'!H4>0,'Balance Sheet'!H17/('Profit & Loss'!H4/365),0) -> 25.80101 | I20: =IF('Profit & Loss'!I4>0,'Balance Sheet'!I17/('Profit & Loss'!I4/365),0) -> 21.153278 | ... K20: =IF('Profit & Loss'!K4>0,'Balance Sheet'!K17/('Profit & Loss'!K4/365),0) -> 18.98169
A21: Inventory Turnover | B21: =IF('Balance Sheet'!B18>0,'Profit & Loss'!B4/'Balance Sheet'!B18,0) -> 8.3194846 | C21: =IF('Balance Sheet'!C18>0,'Profit & Loss'!C4/'Balance Sheet'!C18,0) -> 9.4275215 | D21: =IF('Balance Sheet'!D18>0,'Profit & Loss'!D4/'Balance Sheet'!D18,0) -> 9.8648449 | E21: =IF('Balance Sheet'!E18>0,'Profit & Loss'!E4/'Balance Sheet'!E18,0) -> 8.5835497 | F21: =IF('Balance Sheet'!F18>0,'Profit & Loss'!F4/'Balance Sheet'!F18,0) -> 6.7839165 | G21: =IF('Balance Sheet'!G18>0,'Profit & Loss'!G4/'Balance Sheet'!G18,0) -> 7.7248687 | H21: =IF('Balance Sheet'!H18>0,'Profit & Loss'!H4/'Balance Sheet'!H18,0) -> 7.7761271 | I21: =IF('Balance Sheet'!I18>0,'Profit & Loss'!I4/'Balance Sheet'!I18,0) -> 7.1948244 | ... K21: =IF('Balance Sheet'!K18>0,'Profit & Loss'!K4/'Balance Sheet'!K18,0) -> 7.8309659
A23: Return on Equity | B23: =IF(SUM('Balance Sheet'!B4:B5)>0,'Profit & Loss'!B12/SUM('Balance Sheet'!B4:B5),"") -> 0.11884164 | C23: =IF(SUM('Balance Sheet'!C4:C5)>0,'Profit & Loss'!C12/SUM('Balance Sheet'!C4:C5),"") -> 0.12418844 | D23: =IF(SUM('Balance Sheet'!D4:D5)>0,'Profit & Loss'!D12/SUM('Balance Sheet'!D4:D5),"") -> 0.20422437 | E23: =IF(SUM('Balance Sheet'!E4:E5)>0,'Profit & Loss'!E12/SUM('Balance Sheet'!E4:E5),"") -> 0.13294164 | F23: =IF(SUM('Balance Sheet'!F4:F5)>0,'Profit & Loss'!F12/SUM('Balance Sheet'!F4:F5),"") -> 0.0031784387 | G23: =IF(SUM('Balance Sheet'!G4:G5)>0,'Profit & Loss'!G12/SUM('Balance Sheet'!G4:G5),"") -> 0.043588415 | H23: =IF(SUM('Balance Sheet'!H4:H5)>0,'Profit & Loss'!H12/SUM('Balance Sheet'!H4:H5),"") -> 0.13957877 | I23: =IF(SUM('Balance Sheet'!I4:I5)>0,'Profit & Loss'!I12/SUM('Balance Sheet'!I4:I5),"") -> 0.18240674 | ... K23: =IF(SUM('Balance Sheet'!K4:K5)>0,'Profit & Loss'!K12/SUM('Balance Sheet'!K4:K5),"") -> 0.16782569
A24: Return on Capital Emp | C24: =IF((B4+B5+B6+C4+C5+C6)>0,('Profit & Loss'!C10+'Profit & Loss'!C9)*2/(B4+B5+B6+C4+C5+C6),"") -> 0.13642201 | D24: =IF((C4+C5+C6+D4+D5+D6)>0,('Profit & Loss'!D10+'Profit & Loss'!D9)*2/(C4+C5+C6+D4+D5+D6),"") -> 0.16719101 | E24: =IF((D4+D5+D6+E4+E5+E6)>0,('Profit & Loss'!E10+'Profit & Loss'!E9)*2/(D4+D5+D6+E4+E5+E6),"") -> 0.13652935 | F24: =IF((E4+E5+E6+F4+F5+F6)>0,('Profit & Loss'!F10+'Profit & Loss'!F9)*2/(E4+E5+E6+F4+F5+F6),"") -> 0.065916538 | G24: =IF((F4+F5+F6+G4+G5+G6)>0,('Profit & Loss'!G10+'Profit & Loss'!G9)*2/(F4+F5+F6+G4+G5+G6),"") -> 0.075821697 | H24: =IF((G4+G5+G6+H4+H5+H6)>0,('Profit & Loss'!H10+'Profit & Loss'!H9)*2/(G4+G5+G6+H4+H5+H6),"") -> 0.11646663 | I24: =IF((H4+H5+H6+I4+I5+I6)>0,('Profit & Loss'!I10+'Profit & Loss'!I9)*2/(H4+H5+H6+I4+I5+I6),"") -> 0.14553226 | J24: =IF((I4+I5+I6+J4+J5+J6)>0,('Profit & Loss'!J10+'Profit & Loss'!J9)*2/(I4+I5+I6+J4+J5+J6),"") -> 0.14509796 | K24: =IF((J4+J5+J6+K4+K5+K6)>0,('Profit & Loss'!K10+'Profit & Loss'!K9)*2/(J4+J5+J6+K4+K5+K6),"") -> 0.14787565

Sheet Cash Flow
A1: ='Balance Sheet'!A1 -> MAHINDRA & MAHINDRA LTD | E1: =UPDATE | J1: SCREENER.IN
A3: Narration | B3: Mar-16 | C3: Mar-17 | D3: Mar-18 | E3: Mar-19 | F3: Mar-20 | G3: Mar-21 | H3: Mar-22 | I3: Mar-23 | J3: Mar-24 | K3: Mar-25
A4: Cash from Operating Activity | B4: ='Data Sheet'!B82 -> 2384.76 | C4: ='Data Sheet'!C82 -> 183.09 | D4: ='Data Sheet'!D82 -> 681.86 | E4: ='Data Sheet'!E82 -> -4347.29 | F4: ='Data Sheet'!F82 -> -1456.93 | G4: ='Data Sheet'!G82 -> 17908.83 | H4: ='Data Sheet'!H82 -> 9247.55 | I4: ='Data Sheet'!I82 -> -7074.02 | ... K4: ='Data Sheet'!K82 -> 3175.81
A5: Cash from Investing Activity | B5: ='Data Sheet'!B83 -> -5505.97 | C5: ='Data Sheet'!C83 -> -5875.29 | D5: ='Data Sheet'!D83 -> -5467.22 | E5: ='Data Sheet'!E83 -> -7173.97 | F5: ='Data Sheet'!F83 -> -6869.79 | G5: ='Data Sheet'!G83 -> -19685.5 | H5: ='Data Sheet'!H83 -> -3251.95 | I5: ='Data Sheet'!I83 -> -8866.27 | ... K5: ='Data Sheet'!K83 -> -18616.13
A6: Cash from Financing Activity | B6: ='Data Sheet'!B84 -> 2966.81 | C6: ='Data Sheet'!C84 -> 6107.97 | D6: ='Data Sheet'!D84 -> 6314.5 | E6: ='Data Sheet'!E84 -> 13193.63 | F6: ='Data Sheet'!F84 -> 6932.75 | G6: ='Data Sheet'!G84 -> 406.23 | H6: ='Data Sheet'!H84 -> -5882.6 | I6: ='Data Sheet'!I84 -> 15946.11 | ... K6: ='Data Sheet'!K84 -> 15834.11
A7: Net Cash Flow | B7: ='Data Sheet'!B85 -> -154.4 | C7: ='Data Sheet'!C85 -> 415.77 | D7: ='Data Sheet'!D85 -> 1529.14 | E7: ='Data Sheet'!E85 -> 1672.37 | F7: ='Data Sheet'!F85 -> -1393.97 | G7: ='Data Sheet'!G85 -> -1370.44 | H7: ='Data Sheet'!H85 -> 113 | I7: ='Data Sheet'!I85 -> 5.82 | ... K7: ='Data Sheet'!K85 -> 393.79

Sheet Balance Sheet 2
A1: Narration | B1: Equity Share Capital | C1: Reserves | D1: Borrowings | E1: Other Liabilities | F1: Total | G1: Column7 | H1: Net Block | I1: Capital Work in Progress | J1: Investments | K1: Other Assets | L1: Total_1 | M1: Column13 | N1: Working Capital | O1: Debtors | P1: Inventory | Q1: Column17 | R1: Debtor Days | S1: Inventory Turnover | T1: Column20 | U1: Return on Equity | V1: Return on Capital Emp
A2: 42430 | B2: 270.4 | C2: 26222.25 | D2: 41552.93 | E2: 31806.24 | F2: 99851.82 | H2: 20584.71 | I2: 2371.35 | J2: 11602.58 | K2: 65293.18 | L2: 99851.82 | N2: 33486.94 | O2: 5817.6 | P2: 9116.12 | R2: 27.99821 | S2: 8.3194846 | U2: 0.11884164
A3: 42795 | B3: 310.55 | C3: 29467.1 | D3: 48761.91 | E3: 35295.92 | F3: 113835.48 | H3: 20989.01 | I3: 4278.94 | J3: 14662.44 | K3: 73905.09 | L3: 113835.48 | N3: 38609.17 | O3: 7199.26 | P3: 8886.01 | R3: 31.367246 | S3: 9.4275215 | U3: 0.12418844 | V3: 0.13642201
A4: 43160 | B4: 543.13 | C4: 36232.06 | D4: 55897.92 | E4: 43696.2 | F4: 136369.31 | H4: 26181.9 | I4: 4269.47 | J4: 16017.61 | K4: 89900.33 | L4: 136369.31 | N4: 46204.13 | O4: 8489.82 | P4: 9335.57 | R4: 33.648077 | S4: 9.8648449 | U4: 0.20422437 | V4: 0.16719101
A5: 43525 | B5: 543.96 | C5: 39439.45 | D5: 70848.3 | E5: 51056.95 | F5: 161888.66 | H5: 28982.74 | I5: 4759.84 | J5: 18268.1 | K5: 109877.98 | L5: 161888.66 | N5: 58821.03 | O5: 8677.89 | P5: 12200.16 | R5: 30.24646 | S5: 8.5835497 | U5: 0.13294164 | V5: 0.13652935
A6: 43891 | B6: 554.28 | C6: 39415.03 | D6: 82092.28 | E6: 43654.54 | F6: 165716.13 | H6: 29689.27 | I6: 6856.48 | J6: 19210.34 | K6: 109960.04 | L6: 165716.13 | N6: 66305.5 | O6: 6928.28 | P6: 11111.86 | R6: 33.546796 | S6: 6.7839165 | U6: 0.0031784387 | V6: 0.065916538
A7: 44256 | B7: 555.15 | C7: 41026.77 | D7: 80624.83 | E7: 42761.58 | F7: 164968.33 | H7: 21379.68 | I7: 7872.61 | J7: 28777.66 | K7: 106938.38 | L7: 164968.33 | N7: 64176.8 | O7: 6007.76 | P7: 9615.41 | R7: 29.522051 | S7: 7.7248687 | U7: 0.043588415 | V7: 0.075821697
A8: 44621 | B8: 556.06 | C8: 46566.58 | D8: 77605.21 | E8: 47660.64 | F8: 172388.49 | H8: 26018.49 | I8: 6702.81 | J8: 30060.43 | K8: 109606.76 | L8: 172388.49 | N8: 61946.12 | O8: 6373.95 | P8: 11595.82 | R8: 25.80101 | S8: 7.7761271 | U8: 0.13957877 | V8: 0.11646663
A9: 44986 | B9: 556.82 | C9: 55808.97 | D9: 92246.85 | E9: 55670.49 | F9: 204283.13 | H9: 27139.98 | I9: 3968.58 | J9: 35272.42 | K9: 137902.15 | L9: 204283.13 | N9: 82231.66 | O9: 7028.02 | P9: 16854.97 | R9: 21.153278 | S9: 7.1948244 | U9: 0.18240674 | V9: 0.14553226
A10: 45352 | B10: 557.38 | C10: 65633.17 | D10: 108647.25 | E10: 59883.94 | F10: 234721.74 | H10: 28129.41 | I10: 8039.3 | J10: 35208.1 | K10: 163344.93 | L10: 234721.74 | N10: 103460.99 | O10: 7459.4 | P10: 18590.47 | R10: 19.57661 | S10: 7.4811594 | U10: 0.17024545 | V10: 0.14509796
A11: 45717 | B11: 558.15 | C11: 76480.71 | D11: 129024.58 | E11: 69949.72 | F11: 276013.16 | H11: 34636.36 | I11: 8297.64 | J11: 41308.57 | K11: 191770.59 | L11: 276013.16 | N11: 121820.87 | O11: 8279.7 | P11: 20330.93 | R11: 18.98169 | S11: 7.8309659 | U11: 0.16782569 | V11: 0.14787565

Sheet Annual
A1: Years | B1: Sales | C1: Expenses | D1: Operating Profit | E1: Other Income | F1: Depreciation | G1: Interest | H1: Profit before tax | I1: Tax | J1: Net profit | K1: EPS | L1: Price to earning | M1: Price | N1: RATIOS: | O1: Dividend Payout | P1: OPM | Q1: Net Profit Margin
A2: Mar-16 | B2: 75841.42 | C2: 65758.98 | D2: 10082.44 | E2: 1398.83 | F2: 2441.65 | G2: 3367.59 | H2: 5672.03 | I2: 2117.53 | J2: 3148.43 | K2: 25.345597 | L2: 23.883833 | M2: 605.35 | O2: 0.20612178 | P2: 0.13294108 | Q2: =Annual_1[[#This Row],[Net profit]]/Annual_1[[#This Row],[Sales]] -> 0.041513331
A3: Mar-17 | B3: 83773.05 | C3: 73038.22 | D3: 10734.83 | E3: 2076.61 | F3: 2812.72 | G3: 3648.46 | H3: 6350.26 | I3: 2299.73 | J3: 3698.04 | K3: 29.770085 | L3: 21.613979 | M3: 643.45 | O3: 0.21833999 | P3: 0.12814181 | Q3: =Annual_1[[#This Row],[Net profit]]/Annual_1[[#This Row],[Sales]] -> 0.044143552
A4: Mar-18 | B4: 92093.95 | C4: 78867.85 | D4: 13226.1 | E4: 4366.41 | F4: 3279.9 | G4: 3987.09 | H4: 10325.52 | I4: 2367.73 | J4: 7510.39 | K4: 60.41176 | L4: 12.231062 | M4: 738.9 | O4: 0.10847639 | P4: 0.1436153 | Q4: =Annual_1[[#This Row],[Net profit]]/Annual_1[[#This Row],[Sales]] -> 0.081551394
A5: Mar-19 | B5: 104720.68 | C5: 89514.17 | D5: 15206.51 | E5: 2676.45 | F5: 3990.77 | G5: 5021.35 | H5: 8870.84 | I5: 2853.99 | J5: 5315.46 | K5: 42.756274 | L5: 15.761429 | M5: 673.9 | O5: 0.17396989 | P5: 0.14521019 | Q5: =Annual_1[[#This Row],[Net profit]]/Annual_1[[#This Row],[Sales]] -> 0.050758456
A6: Mar-20 | B6: 75381.93 | C6: 65224.18 | D6: 10157.75 | E6: 884.69 | F6: 3366.68 | G6: 6021.15 | H6: 1654.61 | I6: 1975.61 | J6: 127.04 | K6: 1.021879 | L6: 278.84906 | M6: 284.95 | O6: 2.050614 | P6: 0.13475046 | Q6: =Annual_1[[#This Row],[Net profit]]/Annual_1[[#This Row],[Sales]] -> 0.0016852845
A7: Mar-21 | B7: 74277.78 | C7: 62790.76 | D7: 11487.02 | E7: 1151.51 | F7: 3378.11 | G7: 6102.22 | H7: 3158.2 | I7: 1645.81 | J7: 1812.49 | K7: 14.579231 | L7: 54.546773 | M7: 795.25 | O7: 0.53600847 | P7: 0.15464948 | Q7: =Annual_1[[#This Row],[Net profit]]/Annual_1[[#This Row],[Sales]] -> 0.02440151
A8: Mar-22 | B8: 90170.57 | C8: 75487.72 | D8: 14682.85 | E8: 3204.47 | F8: 3507.5 | G8: 5018.05 | H8: 9361.77 | I8: 2108.76 | J8: 6577.32 | K8: 52.906371 | L8: 15.244856 | M8: 806.55 | O8: 0.19529231 | P8: 0.16283417 | Q8: =Annual_1[[#This Row],[Net profit]]/Annual_1[[#This Row],[Sales]] -> 0.07294309
A9: Mar-23 | B9: 121268.55 | C9: 100983.26 | D9: 20285.29 | E9: 3961.45 | F9: 4356.81 | G9: 5829.7 | H9: 14060.23 | I9: 2685.75 | J9: 10281.5 | K9: 82.681946 | L9: 14.013942 | M9: 1158.7 | O9: 0.17601128 | P9: 0.16727577 | Q9: =Annual_1[[#This Row],[Net profit]]/Annual_1[[#This Row],[Sales]] -> 0.084782905
A10: Mar-24 | B10: 139078.27 | C10: 114186.34 | D10: 24891.93 | E10: 3297.85 | F10: 4723.78 | G10: 7488.21 | H10: 15977.79 | I10: 3707.97 | J10: 11268.64 | K10: 90.620346 | L10: 21.202192 | M10: 1921.35 | O10: 0.20873326 | P10: 0.17897785 | Q10: =Annual_1[[#This Row],[Net profit]]/Annual_1[[#This Row],[Sales]] -> 0.081023729
A11: Mar-25 | B11: 159210.82 | C11: 128692.63 | D11: 30518.19 | E11: 3718.47 | F11: 6073.65 | G11: 9083.39 | H11: 19079.62 | I11: 5006.45 | J11: 12929.1 | K11: 103.97346 | L11: 25.639235 | M11: 2665.8 | O11: 0.21844057 | P11: 0.19168415 | Q11: =Annual_1[[#This Row],[Net profit]]/Annual_1[[#This Row],[Sales]] -> 0.08120742
A12: Trailing | B12: 186333.92 | C12: 151094.89 | D12: 35239.03 | E12: 4646.53 | F12: 7408.06 | G12: 9580.04 | H12: 22897.46 | I12: 5993.81 | J12: 15726.45 | K12: 126.46631 | L12: 24.718046 | M12: 3126 | P12: 0.18911763 | Q12: =Annual_1[[#This Row],[Net profit]]/Annual_1[[#This Row],[Sales]] -> 0.084399287
A13: Best Case | B13: 192431.06 | C13: 156038.95 | D13: 36392.106 | E13: 0 | F13: 7408.06 | G13: 9580.04 | H13: 19404.006 | I13: 0.26176746 | J13: 14324.669 | K13: 115.1937 | L13: 24.718046 | M13: 2847.3632 | Q13: =Annual_1[[#This Row],[Net profit]]/Annual_1[[#This Row],[Sales]] -> 0.074440524
A14: Worst Case | B14: 174367.59 | C14: 146684.68 | D14: 27682.908 | E14: 0 | F14: 7408.06 | G14: 9580.04 | H14: 10694.808 | I14: 0.26176746 | J14: 7895.2552 | K14: 63.490728 | L14: 21.393354 | M14: 1358.2796 | Q14: =Annual_1[[#This Row],[Net profit]]/Annual_1[[#This Row],[Sales]] -> 0.045279373

Sheet Quarters (2)
A1: Narration | B1: Sales | C1: Expenses | D1: Operating Profit | E1: Other Income | F1: Depreciation | G1: Interest | H1: Profit before tax | I1: Tax | J1: Net profit | K1: Column11 | L1: OPM
A2: 45170 | B2: 34435.52 | C2: 28705.94 | D2: 5729.58 | E2: 811.95 | F2: 1138.64 | G2: 1835.19 | H2: 3567.7 | I2: 1083.73 | J2: 2347.75 | L2: 0.16638576
A3: 45261 | B3: 35299.39 | C3: 29075.41 | D3: 6223.98 | E3: 755.69 | F3: 1122.59 | G3: 1944.88 | H3: 3912.2 | I3: 935.16 | J3: 2658.4 | L3: 0.17631976
A4: 45352 | B4: 35451.73 | C4: 28847.82 | D4: 6603.91 | E4: 750.44 | F4: 1335.05 | G4: 1989.3 | H4: 4030 | I4: 905.06 | J4: 2754.08 | L4: 0.18627892
A5: 45444 | B5: 37217.72 | C5: 29974.6 | D5: 7243.12 | E5: 733.21 | F5: 1247.77 | G5: 2107.69 | H5: 4620.87 | I5: 1075.09 | J5: 3282.63 | L5: 0.19461482
A6: 45536 | B6: 37923.74 | C6: 30790.34 | D6: 7133.4 | E6: 1125.57 | F6: 1301.99 | G6: 2217.02 | H6: 4739.96 | I6: 1378.9 | J6: 3170.72 | L6: 0.18809854
A7: 45627 | B7: 41470.05 | C7: 33239.32 | D7: 8230.73 | E7: 718.59 | F7: 1495.17 | G7: 2362.16 | H7: 5091.99 | I7: 1467.51 | J7: 3180.58 | L7: 0.19847408
A8: 45717 | B8: 42599.31 | C8: 34688.37 | D8: 7910.94 | E8: 1141.1 | F8: 2028.72 | G8: 2396.52 | H8: 4626.8 | I8: 1084.95 | J8: 3295.17 | L8: 0.18570582
A9: 45809 | B9: 45529.19 | C9: 37301.39 | D9: 8227.8 | E9: 1395.06 | F9: 1547.56 | G9: 2431.19 | H9: 5644.11 | I9: 1267.53 | J9: 4083.32 | L9: 0.18071483
A10: 45901 | B10: 46105.67 | C10: 37165.76 | D10: 8939.91 | E10: 1133.94 | F10: 1668.89 | G10: 2347.03 | H10: 6057.93 | I10: 2094.18 | J10: 3673.32 | L10: 0.19390045
A11: 45992 | B11: 52099.75 | C11: 41939.37 | D11: 10160.38 | E11: 976.43 | F11: 2162.89 | G11: 2405.3 | H11: 6568.62 | I11: 1547.15 | J11: 4674.64 | L11: 0.19501783

Sheet Cash Flow 2
A1: Narration | B1: Cash from Operating Activity | C1: Cash from Investing Activity | D1: Cash from Financing Activity | E1: Net Cash Flow
A2: 42430 | B2: 2384.76 | C2: -5505.97 | D2: 2966.81 | E2: -154.4
A3: 42795 | B3: 183.09 | C3: -5875.29 | D3: 6107.97 | E3: 415.77
A4: 43160 | B4: 681.86 | C4: -5467.22 | D4: 6314.5 | E4: 1529.14
A5: 43525 | B5: -4347.29 | C5: -7173.97 | D5: 13193.63 | E5: 1672.37
A6: 43891 | B6: -1456.93 | C6: -6869.79 | D6: 6932.75 | E6: -1393.97
A7: 44256 | B7: 17908.83 | C7: -19685.5 | D7: 406.23 | E7: -1370.44
A8: 44621 | B8: 9247.55 | C8: -3251.95 | D8: -5882.6 | E8: 113
A9: 44986 | B9: -7074.02 | C9: -8866.27 | D9: 15946.11 | E9: 5.82
A10: 45352 | B10: -5629.95 | C10: -5614.77 | D10: 12281.41 | E10: 1036.69
A11: 45717 | B11: 3175.81 | C11: -18616.13 | D11: 15834.11 | E11: 393.79

Sheet Dashboard
H2: Mahindra & Mahindra Ltd | Financial Dashboard
H4: Annual performance snapshot • FY16 to FY25 • Source: Data Sheet
H5: FY25 Sales | I5: FY25 Sales | J5: FY25 Operating Profit | K5: FY25 Operating Profit | L5: FY25 Net Profit | M5: FY25 Net Profit | N5: FY25 OPM | O5: FY25 OPM | P5: FY25 Cash from Ops | Q5: FY25 Cash from Ops | R5: FY25 Current Price | S5: FY25 Current Price
H6: ='Data Sheet'!K17 -> 159210.82 | J6: ='Data Sheet'!K50 -> 10160.38 | L6: ='Data Sheet'!K29 -> 5006.45 | N6: =IFERROR('Data Sheet'!K50/'Data Sheet'!K17,0) -> 0.063817145 | P6: ='Data Sheet'!K83 -> -18616.13 | R6: ='Data Sheet'!K90 -> 2665.8
